Workbook

Sheet 封面與假設
A1: PDD Holdings Inc. (NASDAQ: PDD)
A2: 完整財務模型 — 首次覆蓋研究
A3: 報告日期：2026-05-25 ｜ 幣別：人民幣百萬元 ｜ 分析師：Claude Code Research
A5: 模型參數 | B5: 數值 | C5: 說明 / 來源
A6: 匯率（USD/RMB）— 2026 預估 | B6: 7.2 | C6: Bloomberg 即期 USD/CNY
A7: 報告幣別 | B7: 人民幣百萬元 | C7: PDD 20-F 申報幣別
A8: 會計年度結束日 | B8: 12月31日 | C8: PDD 會計年度
A9: 歷史年度 | B9: 2021A — 2024A（4 年） | C9: 來自 20-F 申報文件 2023/2024
A10: 預測年度 | B10: 2025E — 2029E（5 年） | C10: 基本情境預測
A11: 實際稅率（基本情境） | B11: 0.105 | C11: 中國高新技術企業稅收優惠
A12: 折現率（WACC）— 參考 | B12: 0.105 | C12: 供 Task 3 DCF 使用（權益成本加權）
A13: 永續成長率（g） | B13: 0.03 | C13: 長期中國 + 全球電商平均水準
A14: 稀釋後流通股數（百萬股，2024） | B14: 1450 | C14: PDD 2024 20-F 平均稀釋 ADS x 1
A15: 市值估計（美元十億，2026 Q1） | B15: 150 | C15: 參考點
A18: 顏色編碼說明
A19: 藍色字體 = 硬編碼輸入
A20: 黑色字體 = 公式 / 計算
A21: 綠色字體 = 跨表引用
A22: 黃色標示 = 小計 / 合計
A24: 模型工作表索引
A25: 1. 封面與假設 — 本頁
A26: 2. 收入模型 — 詳細產品與地區分解（25 個產品行 + 18 個地區行）
A27: 3. 損益表 — 完整損益表（45 個項目 × 9 年）
A28: 4. 現金流量表 — 營業 + 投資 + 籌資活動
A29: 5. 資產負債表 — 資產 + 負債 + 權益（含平衡驗證）
A30: 6. 情境分析 — 樂觀 / 基本 / 悲觀情境比較與假設
A31: 7. DCF輸入 — 供 Task 3 估值使用的無槓桿 FCF

Sheet 收入模型
A1: PDD Holdings — 收入模型（人民幣百萬元）
A2: 依產品/業務分部與地區詳細分解
B4: 2021A | C4: 2022A | D4: 2023A | E4: 2024A | F4: 2025E | G4: 2026E | H4: 2027E | I4: 2028E | J4: 2029E
A5: A. 依產品/業務分部劃分收入
A6: 拼多多核心平台（中國）
A7: 在線行銷服務（廣告收入） | B7: 60500 | C7: 80500 | D7: 120300 | E7: 150500 | F7: 168000 | G7: 185000 | H7: 200000 | I7: 213000 | J7: 224000
A8: 交易服務費 | B8: 12134 | C8: 21567 | D8: 31046 | E8: 47443 | F8: 56000 | G8: 64000 | H8: 71000 | I8: 77000 | J8: 82000
A9: 多多買菜 | B9: 4500 | C9: 8500 | D9: 13500 | E9: 18500 | F9: 23000 | G9: 27500 | H9: 31500 | I9: 34500 | J9: 36500
A10: 拼多多合計（中國） | B10: =SUM(B7:B9) | C10: =SUM(C7:C9) | D10: =SUM(D7:D9) | E10: =SUM(E7:E9) | F10: =SUM(F7:F9) | G10: =SUM(G7:G9) | H10: =SUM(H7:H9) | I10: =SUM(I7:I9) | J10: =SUM(J7:J9)
A12: Temu 全球電商
A13: Temu — 全託管模式 | B13: 0 | C13: 4500 | D13: 75000 | E13: 168000 | F13: 196000 | G13: 220000 | H13: 240000 | I13: 255000 | J13: 265000
A14: Temu — 半託管模式 | B14: 0 | C14: 0 | D14: 0 | E14: 8500 | F14: 25000 | G14: 48000 | H14: 68000 | I14: 85000 | J14: 100000
A15: Temu — Local-to-Local（L2L） | B15: 0 | C15: 0 | D15: 0 | E15: 1500 | F15: 6000 | G15: 15000 | H15: 28000 | I15: 42000 | J15: 56000
A16: Temu 合計（全球） | B16: =SUM(B13:B15) | C16: =SUM(C13:C15) | D16: =SUM(D13:D15) | E16: =SUM(E13:E15) | F16: =SUM(F13:F15) | G16: =SUM(G13:G15) | H16: =SUM(H13:H15) | I16: =SUM(I13:I15) | J16: =SUM(J13:J15)
A18: 其他新業務
A19: 多多視頻（短視頻電商廣告） | B19: 0 | C19: 0 | D19: 1000 | E19: 4500 | F19: 12000 | G19: 22000 | H19: 32000 | I19: 42000 | J19: 50000
A20: 多多本地生活 | B20: 0 | C20: 0 | D20: 0 | E20: 800 | F20: 2500 | G20: 5000 | H20: 8500 | I20: 12500 | J20: 17000
A21: 其他收入 | B21: 816 | C21: 1491 | D21: 6793 | E21: 4393 | F21: 3500 | G21: 4000 | H21: 4500 | I21: 5000 | J21: 5500
A22: 新業務合計 | B22: =SUM(B19:B21) | C22: =SUM(C19:C21) | D22: =SUM(D19:D21) | E22: =SUM(E19:E21) | F22: =SUM(F19:F21) | G22: =SUM(G19:G21) | H22: =SUM(H19:H21) | I22: =SUM(I19:I21) | J22: =SUM(J19:J21)
A24: 總收入（人民幣百萬元） | B24: =B10+B16+B22 | C24: =C10+C16+C22 | D24: =D10+D16+D22 | E24: =E10+E16+E22 | F24: =F10+F16+F22 | G24: =G10+G16+G22 | H24: =H10+H16+H22 | I24: =I10+I16+I22 | J24: =J10+J16+J22
A25: 收入年增率 % | B25: – | C25: =C24/B24-1 | D25: =D24/C24-1 | E25: =E24/D24-1 | F25: =F24/E24-1 | G25: =G24/F24-1 | H25: =H24/G24-1 | I25: =I24/H24-1 | J25: =J24/I24-1
A27: 業務分部佔總收入比例 %
A28: 拼多多（中國）佔比 % | B28: =B10/B24 | C28: =C10/C24 | D28: =D10/D24 | E28: =E10/E24 | F28: =F10/F24 | G28: =G10/G24 | H28: =H10/H24 | I28: =I10/I24 | J28: =J10/J24
A29: Temu（全球）佔比 % | B29: =B16/B24 | C29: =C16/C24 | D29: =D16/D24 | E29: =E16/E24 | F29: =F16/F24 | G29: =G16/G24 | H29: =H16/H24 | I29: =I16/I24 | J29: =J16/J24
A30: 新業務佔比 % | B30: =B22/B24 | C30: =C22/C24 | D30: =D22/D24 | E30: =E22/E24 | F30: =F22/F24 | G30: =G22/G24 | H30: =H22/H24 | I30: =I22/I24 | J30: =J22/J24
A33: B. 依地區劃分收入
B34: 2021A | C34: 2022A | D34: 2023A | E34: 2024A | F34: 2025E | G34: 2026E | H34: 2027E | I34: 2028E | J34: 2029E
A35: 大中華地區
A36: 中國大陸 | B36: 77134 | C36: 109491 | D36: 165846 | E36: 220443 | F36: 257000 | G36: 290500 | H36: 322000 | I36: 350000 | J36: 375000
A37: 香港 / 台灣 / 澳門 | B37: 0 | C37: 1067 | D37: 1500 | E37: 1800 | F37: 2200 | G37: 2500 | H37: 2800 | I37: 3000 | J37: 3200
A38: 大中華合計 | B38: =SUM(B36:B37) | C38: =SUM(C36:C37) | D38: =SUM(D36:D37) | E38: =SUM(E36:E37) | F38: =SUM(F36:F37) | G38: =SUM(G36:G37) | H38: =SUM(H36:H37) | I38: =SUM(I36:I37) | J38: =SUM(J36:J37)
A39: 北美
A40: 美國 | B40: 0 | C40: 2500 | D40: 50000 | E40: 105000 | F40: 120000 | G40: 135000 | H40: 150000 | I40: 162000 | J40: 173000
A41: 加拿大 | B41: 0 | C41: 0 | D41: 4000 | E41: 9000 | F41: 12000 | G41: 15000 | H41: 17500 | I41: 20000 | J41: 22000
A42: 墨西哥 | B42: 0 | C42: 0 | D42: 1500 | E42: 5500 | F42: 9000 | G42: 13000 | H42: 17000 | I42: 21000 | J42: 24500
A43: 北美合計 | B43: =SUM(B40:B42) | C43: =SUM(C40:C42) | D43: =SUM(D40:D42) | E43: =SUM(E40:E42) | F43: =SUM(F40:F42) | G43: =SUM(G40:G42) | H43: =SUM(H40:H42) | I43: =SUM(I40:I42) | J43: =SUM(J40:J42)
A44: 歐洲
A45: 英國 | B45: 0 | C45: 0 | D45: 4500 | E45: 10500 | F45: 14500 | G45: 18500 | H45: 22000 | I45: 25000 | J45: 27500
A46: 德國 | B46: 0 | C46: 0 | D46: 3500 | E46: 9000 | F46: 13000 | G46: 17000 | H46: 21000 | I46: 24500 | J46: 27000
A47: 法國 | B47: 0 | C47: 0 | D47: 2500 | E47: 6500 | F47: 9500 | G47: 12500 | H47: 15500 | I47: 18000 | J47: 20000
...

Sheet 損益表
A1: PDD Holdings — 損益表（人民幣百萬元）
A2: 完整損益表：4 年歷史（2021A-2024A）+ 5 年預測（2025E-2029E）
B4: 2021A | C4: 2022A | D4: 2023A | E4: 2024A | F4: 2025E | G4: 2026E | H4: 2027E | I4: 2028E | J4: 2029E
A5: 收入
A6: 總收入 | B6: =收入模型!B24 | C6: =收入模型!C24 | D6: =收入模型!D24 | E6: =收入模型!E24 | F6: =收入模型!F24 | G6: =收入模型!G24 | H6: =收入模型!H24 | I6: =收入模型!I24 | J6: =收入模型!J24
A7: 收入年增率 % | B7: – | C7: =C6/B6-1 | D7: =D6/C6-1 | E7: =E6/D6-1 | F7: =F6/E6-1 | G7: =G6/F6-1 | H7: =H6/G6-1 | I7: =I6/H6-1 | J7: =J6/I6-1
A9: 營業成本
A10: 履約物流成本 | B10: 12500 | C10: 15500 | D10: 35000 | E10: 65000 | F10: 79000 | G10: 92000 | H10: 105000 | I10: 116000 | J10: 125000
A11: 存貨與商品採購 | B11: 5500 | C11: 7500 | D11: 22000 | E11: 51000 | F11: 64000 | G11: 76500 | H11: 88500 | I11: 99000 | J11: 108500
A12: 支付通道費用 | B12: 8547 | C12: 7996 | D12: 23424 | E12: 27234 | F12: 32500 | G12: 38500 | H12: 44500 | I12: 49500 | J12: 54000
A13: 伺服器與頻寬 | B13: 4500 | C13: 3500 | D13: 9500 | E13: 11500 | F13: 13500 | G13: 15500 | H13: 17500 | I13: 19000 | J13: 20500
A14: 其他營業成本 | B14: 1500 | C14: 1500 | D14: 3000 | E14: 3500 | F14: 4000 | G14: 4500 | H14: 5000 | I14: 5500 | J14: 6000
A15: 營業成本合計 | B15: =SUM(B10:B14) | C15: =SUM(C10:C14) | D15: =SUM(D10:D14) | E15: =SUM(E10:E14) | F15: =SUM(F10:F14) | G15: =SUM(G10:G14) | H15: =SUM(H10:H14) | I15: =SUM(I10:I14) | J15: =SUM(J10:J14)
A17: 毛利 | B17: =B6-B15 | C17: =C6-C15 | D17: =D6-D15 | E17: =E6-E15 | F17: =F6-F15 | G17: =G6-G15 | H17: =H6-H15 | I17: =I6-I15 | J17: =J6-J15
A18: 毛利率 % | B18: =B17/B6 | C18: =C17/C6 | D18: =D17/D6 | E18: =E17/E6 | F18: =F17/F6 | G18: =G17/G6 | H18: =H17/H6 | I18: =I17/I6 | J18: =J17/J6
A20: 營業費用
A21: 銷售與行銷 — 人事費用 | B21: 3500 | C21: 4500 | D21: 5500 | E21: 7500 | F21: 9500 | G21: 11500 | H21: 13500 | I21: 15000 | J21: 16500
A22: 銷售與行銷 — 廣告與促銷（Temu 主力） | B22: 27408 | C22: 47894 | D22: 70189 | E22: 95250 | F22: 113000 | G22: 130500 | H22: 146500 | I22: 159000 | J22: 169000
A23: 銷售與行銷 — 其他（補貼/優惠券） | B23: 2500 | C23: 2000 | D23: 6500 | E23: 7000 | F23: 8500 | G23: 10000 | H23: 11500 | I23: 12500 | J23: 13500
A24: 銷售與行銷費用合計 | B24: =SUM(B21:B23) | C24: =SUM(C21:C23) | D24: =SUM(D21:D23) | E24: =SUM(E21:E23) | F24: =SUM(F21:F23) | G24: =SUM(G21:G23) | H24: =SUM(H21:H23) | I24: =SUM(I21:I23) | J24: =SUM(J21:J23)
A25: S&M 佔收入比例 % | B25: =B24/B6 | C25: =C24/C6 | D25: =D24/D6 | E25: =E24/E6 | F25: =F24/F6 | G25: =G24/G6 | H25: =H24/H6 | I25: =I24/I6 | J25: =J24/J6
A27: 研發 — 人事費用 | B27: 7993 | C27: 8886 | D27: 8955 | E27: 11250 | F27: 13500 | G27: 16000 | H27: 18500 | I27: 20500 | J27: 22500
A28: 研發 — 其他費用 | B28: 1000 | C28: 1500 | D28: 2000 | E28: 2500 | F28: 3000 | G28: 3500 | H28: 4000 | I28: 4500 | J28: 5000
A29: 研發費用合計 | B29: =SUM(B27:B28) | C29: =SUM(C27:C28) | D29: =SUM(D27:D28) | E29: =SUM(E27:E28) | F29: =SUM(F27:F28) | G29: =SUM(G27:G28) | H29: =SUM(H27:H28) | I29: =SUM(I27:I28) | J29: =SUM(J27:J28)
A30: R&D 佔收入比例 % | B30: =B29/B6 | C30: =C29/C6 | D30: =D29/D6 | E30: =E29/E6 | F30: =F29/F6 | G30: =G29/G6 | H30: =H29/H6 | I30: =I29/I6 | J30: =J29/J6
A32: 管理費用 — 人事 | B32: 1200 | C32: 1800 | D32: 2300 | E32: 3000 | F32: 3800 | G32: 4700 | H32: 5500 | I32: 6200 | J32: 6800
A33: 管理費用 — 其他 | B33: 344 | C33: 679 | D33: 766 | E33: 1150 | F33: 1500 | G33: 1900 | H33: 2300 | I33: 2600 | J33: 2900
A34: 管理費用合計 | B34: =SUM(B32:B33) | C34: =SUM(C32:C33) | D34: =SUM(D32:D33) | E34: =SUM(E32:E33) | F34: =SUM(F32:F33) | G34: =SUM(G32:G33) | H34: =SUM(H32:H33) | I34: =SUM(I32:I33) | J34: =SUM(J32:J33)
A35: G&A 佔收入比例 % | B35: =B34/B6 | C35: =C34/C6 | D35: =D34/D6 | E35: =E34/E6 | F35: =F34/F6 | G35: =G34/G6 | H35: =H34/H6 | I35: =I34/I6 | J35: =J34/J6
A36: 折舊與攤銷 | B36: 600 | C36: 800 | D36: 1200 | E36: 1650 | F36: 2100 | G36: 2600 | H36: 3200 | I36: 3800 | J36: 4400
A38: 營業費用合計 | B38: =B24+B29+B34+B36 | C38: =C24+C29+C34+C36 | D38: =D24+D29+D34+D36 | E38: =E24+E29+E34+E36 | F38: =F24+F29+F34+F36 | G38: =G24+G29+G34+G36 | H38: =H24+H29+H34+H36 | I38: =I24+I29+I34+I36 | J38: =J24+J29+J34+J36
A39: 營業費用佔收入比例 % | B39: =B38/B6 | C39: =C38/C6 | D39: =D38/D6 | E39: =E38/E6 | F39: =F38/F6 | G39: =G38/G6 | H39: =H38/H6 | I39: =I38/I6 | J39: =J38/J6
A41: EBITDA | B41: =B17-B24-B29-B34 | C41: =C17-C24-C29-C34 | D41: =D17-D24-D29-D34 | E41: =E17-E24-E29-E34 | F41: =F17-F24-F29-F34 | G41: =G17-G24-G29-G34 | H41: =H17-H24-H29-H34 | I41: =I17-I24-I29-I34 | J41: =J17-J24-J29-J34
A42: EBITDA 利潤率 % | B42: =B41/B6 | C42: =C41/C6 | D42: =D41/D6 | E42: =E41/E6 | F42: =F41/F6 | G42: =G41/G6 | H42: =H41/H6 | I42: =I41/I6 | J42: =J41/J6
A44: EBIT / 營業利潤 | B44: =B41-B36 | C44: =C41-C36 | D44: =D41-D36 | E44: =E41-E36 | F44: =F41-F36 | G44: =G41-G36 | H44: =H41-H36 | I44: =I41-I36 | J44: =J41-J36
A45: EBIT 利潤率 % | B45: =B44/B6 | C45: =C44/C6 | D45: =D44/D6 | E45: =E44/E6 | F45: =F44/F6 | G45: =G44/G6 | H45: =H44/H6 | I45: =I44/I6 | J45: =J44/J6
A47: 營業外項目
A48: 利息收入（大額現金部位） | B48: 1200 | C48: 4500 | D48: 8500 | E48: 13500 | F48: 16500 | G48: 19500 | H48: 22500 | I48: 25500 | J48: 28500
A49: 利息費用 | B49: -100 | C49: -150 | D49: -200 | E49: -350 | F49: -500 | G49: -650 | H49: -800 | I49: -950 | J49: -1100
A50: 其他收入 / （費用），淨額 | B50: -2300 | C50: -100 | D50: 600 | E50: 2500 | F50: 1500 | G50: 1800 | H50: 2000 | I50: 2200 | J50: 2500
...

Sheet 現金流量表
A1: PDD Holdings — 現金流量表（人民幣百萬元）
A2: 間接法，由淨利潤起算
B4: 2021A | C4: 2022A | D4: 2023A | E4: 2024A | F4: 2025E | G4: 2026E | H4: 2027E | I4: 2028E | J4: 2029E
A5: 營業活動
A6: 淨利潤（GAAP） | B6: =損益表!B57 | C6: =損益表!C57 | D6: =損益表!D57 | E6: =損益表!E57 | F6: =損益表!F57 | G6: =損益表!G57 | H6: =損益表!H57 | I6: =損益表!I57 | J6: =損益表!J57
A7: 加：折舊與攤銷 | B7: =損益表!B36 | C7: =損益表!C36 | D7: =損益表!D36 | E7: =損益表!E36 | F7: =損益表!F36 | G7: =損益表!G36 | H7: =損益表!H36 | I7: =損益表!I36 | J7: =損益表!J36
A8: 加：股權激勵費用（SBC） | B8: =損益表!B60 | C8: =損益表!C60 | D8: =損益表!D60 | E8: =損益表!E60 | F8: =損益表!F60 | G8: =損益表!G60 | H8: =損益表!H60 | I8: =損益表!I60 | J8: =損益表!J60
A9: Δ 應收帳款 | B9: -5500 | C9: -2500 | D9: -8500 | E9: -12000 | F9: -8500 | G9: -7500 | H9: -6500 | I9: -5500 | J9: -4500
A10: Δ 存貨（Temu 履約緩衝） | B10: -2500 | C10: -1500 | D10: -8500 | E10: -16500 | F10: -12000 | G10: -10500 | H10: -9000 | I10: -7500 | J10: -6000
A11: Δ 商家保證金與應付帳款 | B11: 15500 | C11: 18500 | D11: 35500 | E11: 65500 | F11: 55000 | G11: 50000 | H11: 45000 | I11: 38500 | J11: 33500
A12: Δ 其他營運資金 | B12: 3500 | C12: 5500 | D12: 6500 | E12: 8500 | F12: 7500 | G12: 7000 | H12: 6500 | I12: 6000 | J12: 5500
A13: 營運資金變動合計 | B13: =SUM(B9:B12) | C13: =SUM(C9:C12) | D13: =SUM(D9:D12) | E13: =SUM(E9:E12) | F13: =SUM(F9:F12) | G13: =SUM(G9:G12) | H13: =SUM(H9:H12) | I13: =SUM(I9:I12) | J13: =SUM(J9:J12)
A15: 營業活動現金流（CFO） | B15: =B6+B7+B8+B13 | C15: =C6+C7+C8+C13 | D15: =D6+D7+D8+D13 | E15: =E6+E7+E8+E13 | F15: =F6+F7+F8+F13 | G15: =G6+G7+G8+G13 | H15: =H6+H7+H8+H13 | I15: =I6+I7+I8+I13 | J15: =J6+J7+J8+J13
A16: CFO 佔收入比例 % | B16: =B15/損益表!B6 | C16: =C15/損益表!C6 | D16: =D15/損益表!D6 | E16: =E15/損益表!E6 | F16: =F15/損益表!F6 | G16: =G15/損益表!G6 | H16: =H15/損益表!H6 | I16: =I15/損益表!I6 | J16: =J15/損益表!J6
A18: 投資活動
A19: 資本支出（CapEx） | B19: -1500 | C19: -2000 | D19: -3500 | E19: -5500 | F19: -7500 | G19: -9500 | H19: -11500 | I19: -13000 | J19: -14000
A20: CapEx 佔收入比例 % | B20: =-B19/損益表!B6 | C20: =-C19/損益表!C6 | D20: =-D19/損益表!D6 | E20: =-E19/損益表!E6 | F20: =-F19/損益表!F6 | G20: =-G19/損益表!G6 | H20: =-H19/損益表!H6 | I20: =-I19/損益表!I6 | J20: =-J19/損益表!J6
A21: Δ 短期投資 | B21: -15000 | C21: -25000 | D21: -35000 | E21: -55000 | F21: -50000 | G21: -45000 | H21: -40000 | I21: -35000 | J21: -30000
A22: 併購與其他投資活動 | B22: -1500 | C22: -2500 | D22: -3500 | E22: -5500 | F22: -4500 | G22: -4000 | H22: -3500 | I22: -3000 | J22: -2500
A24: 投資活動現金流（CFI） | B24: =SUM(B19:B22) | C24: =SUM(C19:C22) | D24: =SUM(D19:D22) | E24: =SUM(E19:E22) | F24: =SUM(F19:F22) | G24: =SUM(G19:G22) | H24: =SUM(H19:H22) | I24: =SUM(I19:I22) | J24: =SUM(J19:J22)
A26: 自由現金流（CFO - CapEx） | B26: =B15+B19 | C26: =C15+C19 | D26: =D15+D19 | E26: =E15+E19 | F26: =F15+F19 | G26: =G15+G19 | H26: =H15+H19 | I26: =I15+I19 | J26: =J15+J19
A27: FCF 佔收入比例 % | B27: =B26/損益表!B6 | C27: =C26/損益表!C6 | D27: =D26/損益表!D6 | E27: =E26/損益表!E6 | F27: =F26/損益表!F6 | G27: =G26/損益表!G6 | H27: =H26/損益表!H6 | I27: =I26/損益表!I6 | J27: =J26/損益表!J6
A29: 籌資活動
A30: 債務發行 / （償還），淨額 | B30: 0 | C30: 0 | D30: 0 | E30: 0 | F30: 0 | G30: 0 | H30: 0 | I30: 0 | J30: 0
A31: 股權發行（員工持股） | B31: 800 | C31: 500 | D31: 1500 | E31: 1200 | F31: 800 | G31: 500 | H31: 500 | I31: 500 | J31: 500
A32: 股份回購 | B32: 0 | C32: 0 | D32: 0 | E32: 0 | F32: 0 | G32: 0 | H32: 0 | I32: 0 | J32: 0
A33: 已派發股利 | B33: 0 | C33: 0 | D33: 0 | E33: 0 | F33: 0 | G33: 0 | H33: 0 | I33: 0 | J33: 0
A34: 其他籌資活動 | B34: -500 | C34: -500 | D34: -800 | E34: -1200 | F34: -1000 | G34: -1000 | H34: -1000 | I34: -1000 | J34: -1000
A36: 籌資活動現金流（CFF） | B36: =SUM(B30:B34) | C36: =SUM(C30:C34) | D36: =SUM(D30:D34) | E36: =SUM(E30:E34) | F36: =SUM(F30:F34) | G36: =SUM(G30:G34) | H36: =SUM(H30:H34) | I36: =SUM(I30:I34) | J36: =SUM(J30:J34)
A38: 現金淨變動 | B38: =B15+B24+B36 | C38: =C15+C24+C36 | D38: =D15+D24+D36 | E38: =E15+E24+E36 | F38: =F15+F24+F36 | G38: =G15+G24+G36 | H38: =H15+H24+H36 | I38: =I15+I24+I36 | J38: =J15+J24+J36
A39: 期初現金及約當現金 | B39: 32000 | C39: =B40 | D39: =C40 | E39: =D40 | F39: =E40 | G39: =F40 | H39: =G40 | I39: =H40 | J39: =I40
A40: 期末現金及約當現金 | B40: =B38+B39 | C40: =C38+C39 | D40: =D38+D39 | E40: =E38+E39 | F40: =F38+F39 | G40: =G38+G39 | H40: =H38+H39 | I40: =I38+I39 | J40: =J38+J39

Sheet 資產負債表
A1: PDD Holdings — 資產負債表（人民幣百萬元）
A2: 年末餘額，含平衡驗證
B4: 2021A | C4: 2022A | D4: 2023A | E4: 2024A | F4: 2025E | G4: 2026E | H4: 2027E | I4: 2028E | J4: 2029E
A5: 流動資產
A6: 現金及約當現金 | B6: =現金流量表!B40 | C6: =現金流量表!C40 | D6: =現金流量表!D40 | E6: =現金流量表!E40 | F6: =現金流量表!F40 | G6: =現金流量表!G40 | H6: =現金流量表!H40 | I6: =現金流量表!I40 | J6: =現金流量表!J40
A7: 短期投資 | B7: 93000 | C7: 118000 | D7: 153000 | E7: 208000 | F7: 258000 | G7: 303000 | H7: 343000 | I7: 378000 | J7: 408000
A8: 應收帳款，淨額 | B8: 4500 | C8: 7000 | D8: 15500 | E8: 27500 | F8: 36000 | G8: 43500 | H8: 50000 | I8: 55500 | J8: 60000
A9: 存貨 | B9: 800 | C9: 2300 | D9: 10800 | E9: 27300 | F9: 39300 | G9: 49800 | H9: 58800 | I9: 66300 | J9: 72300
A10: 預付費用與其他流動資產 | B10: 2500 | C10: 3500 | D10: 5500 | E10: 8500 | F10: 10500 | G10: 12500 | H10: 14500 | I10: 16000 | J10: 17500
A11: 應收關聯方款項 | B11: 1500 | C11: 2500 | D11: 4500 | E11: 6500 | F11: 8500 | G11: 10500 | H11: 12500 | I11: 14000 | J11: 15500
A12: 流動資產合計 | B12: =SUM(B6:B11) | C12: =SUM(C6:C11) | D12: =SUM(D6:D11) | E12: =SUM(E6:E11) | F12: =SUM(F6:F11) | G12: =SUM(G6:G11) | H12: =SUM(H6:H11) | I12: =SUM(I6:I11) | J12: =SUM(J6:J11)
A14: 非流動資產
A15: 不動產廠房設備總額（累計成本） | B15: 5500 | C15: 7500 | D15: 11000 | E15: 16500 | F15: 24000 | G15: 33500 | H15: 45000 | I15: 58000 | J15: 72000
A16: 累計折舊 | B16: -1500 | C16: -2300 | D16: -3500 | E16: -5150 | F16: -7250 | G16: -9850 | H16: -13050 | I16: -16850 | J16: -21250
A17: 不動產廠房設備，淨額 | B17: =B15+B16 | C17: =C15+C16 | D17: =D15+D16 | E17: =E15+E16 | F17: =F15+F16 | G17: =G15+G16 | H17: =H15+H16 | I17: =I15+I16 | J17: =J15+J16
A18: 長期投資 | B18: 12500 | C18: 18500 | D18: 28500 | E18: 42500 | F18: 58500 | G18: 75500 | H18: 92500 | I18: 108500 | J18: 122500
A19: 使用權資產（營業租賃） | B19: 2500 | C19: 3500 | D19: 5500 | E19: 8500 | F19: 12000 | G19: 16000 | H19: 20000 | I19: 24000 | J19: 28000
A20: 無形資產，淨額 | B20: 500 | C20: 1500 | D20: 2500 | E20: 3500 | F20: 4500 | G20: 5500 | H20: 6500 | I20: 7500 | J20: 8500
A21: 商譽 | B21: 0 | C21: 500 | D21: 1500 | E21: 2500 | F21: 3500 | G21: 4500 | H21: 5500 | I21: 6000 | J21: 6500
A22: 遞延所得稅資產 | B22: 3500 | C22: 5500 | D22: 8500 | E22: 12500 | F22: 16500 | G22: 20500 | H22: 24500 | I22: 27500 | J22: 30500
A23: 非流動資產合計 | B23: =B17+B18+B19+B20+B21+B22 | C23: =C17+C18+C19+C20+C21+C22 | D23: =D17+D18+D19+D20+D21+D22 | E23: =E17+E18+E19+E20+E21+E22 | F23: =F17+F18+F19+F20+F21+F22 | G23: =G17+G18+G19+G20+G21+G22 | H23: =H17+H18+H19+H20+H21+H22 | I23: =I17+I18+I19+I20+I21+I22 | J23: =J17+J18+J19+J20+J21+J22
A25: 資產總額 | B25: =B12+B23 | C25: =C12+C23 | D25: =D12+D23 | E25: =E12+E23 | F25: =F12+F23 | G25: =G12+G23 | H25: =H12+H23 | I25: =I12+I23 | J25: =J12+J23
A27: 流動負債
A28: 應付帳款與商家保證金 | B28: 38500 | C28: 56500 | D28: 92500 | E28: 158500 | F28: 213500 | G28: 263500 | H28: 308500 | I28: 347500 | J28: 381500
A29: 應計費用與其他流動負債 | B29: 12500 | C29: 18500 | D29: 31500 | E29: 52500 | F29: 68500 | G29: 83500 | H29: 97500 | I29: 109500 | J29: 119500
A30: 客戶預收款與遞延收入 | B30: 3500 | C30: 5500 | D30: 12500 | E30: 28500 | F30: 40500 | G30: 52500 | H30: 63500 | I30: 73500 | J30: 82500
A31: 短期借款 | B31: 0 | C31: 0 | D31: 0 | E31: 0 | F31: 0 | G31: 0 | H31: 0 | I31: 0 | J31: 0
A32: 短期營業租賃負債 | B32: 800 | C32: 1200 | D32: 1800 | E32: 2500 | F32: 3500 | G32: 4500 | H32: 5500 | I32: 6500 | J32: 7500
A33: 應付所得稅 | B33: 1500 | C33: 2500 | D33: 4500 | E33: 8500 | F33: 11500 | G33: 14500 | H33: 17500 | I33: 19500 | J33: 21500
A34: 流動負債合計 | B34: =SUM(B28:B33) | C34: =SUM(C28:C33) | D34: =SUM(D28:D33) | E34: =SUM(E28:E33) | F34: =SUM(F28:F33) | G34: =SUM(G28:G33) | H34: =SUM(H28:H33) | I34: =SUM(I28:I33) | J34: =SUM(J28:J33)
A36: 非流動負債
A37: 長期借款 | B37: 0 | C37: 0 | D37: 0 | E37: 0 | F37: 0 | G37: 0 | H37: 0 | I37: 0 | J37: 0
A38: 長期營業租賃負債 | B38: 1500 | C38: 2300 | D38: 3500 | E38: 5500 | F38: 7500 | G38: 10000 | H38: 12500 | I38: 15000 | J38: 17500
A39: 遞延所得稅負債 | B39: 200 | C39: 400 | D39: 700 | E39: 1200 | F39: 1700 | G39: 2200 | H39: 2700 | I39: 3200 | J39: 3700
A40: 其他長期負債 | B40: 500 | C40: 800 | D40: 1300 | E40: 2000 | F40: 2700 | G40: 3400 | H40: 4100 | I40: 4800 | J40: 5500
A41: 非流動負債合計 | B41: =SUM(B37:B40) | C41: =SUM(C37:C40) | D41: =SUM(D37:D40) | E41: =SUM(E37:E40) | F41: =SUM(F37:F40) | G41: =SUM(G37:G40) | H41: =SUM(H37:H40) | I41: =SUM(I37:I40) | J41: =SUM(J37:J40)
A43: 負債總額 | B43: =B34+B41 | C43: =C34+C41 | D43: =D34+D41 | E43: =E34+E41 | F43: =F34+F41 | G43: =G34+G41 | H43: =H34+H41 | I43: =I34+I41 | J43: =J34+J41
A45: 股東權益
A46: 普通股 + 資本公積 | B46: 85500 | C46: 89500 | D46: 95500 | E46: 102500 | F46: 108500 | G46: 113500 | H46: 117500 | I46: 121000 | J46: 124000
A47: 庫藏股 | B47: 0 | C47: 0 | D47: 0 | E47: 0 | F47: 0 | G47: 0 | H47: 0 | I47: 0 | J47: 0
...

Sheet 情境分析
A1: PDD Holdings — 情境分析（樂觀 / 基本 / 悲觀）
A2: 三種情境下 5 年（2025E-2029E）預測比較
A4: 指標 | B4: 樂觀情境 | C4: 基本情境 | D4: 悲觀情境 | E4: 說明
A5: 關鍵假設（2025E-2029E）
A6: 收入 CAGR 2024-2029E | B6: 0.225 | C6: 0.165 | D6: 0.085 | E6: 樂觀：Temu 維持 40%+ 成長；悲觀：監管衝擊
A7: Temu CAGR 2024-2029E | B7: 0.35 | C7: 0.225 | D7: 0.1 | E7: 樂觀：Local-to-Local 模式成功；悲觀：de minimis 取消 + 關稅拖累
A8: 拼多多中國 CAGR | B8: 0.11 | C8: 0.075 | D8: 0.02 | E8: 樂觀：份額持續擴大；悲觀：消費疲軟 + 競爭加劇
A9: 2029E 毛利率 % | B9: 0.62 | C9: 0.585 | D9: 0.54 | E9: 樂觀：規模槓桿；悲觀：Temu 結構性拖累
A10: 2029E EBIT 利潤率 % | B10: 0.36 | C10: 0.305 | D10: 0.22 | E10: 營運槓桿假設
A11: 2029E 實際稅率 | B11: 0.115 | C11: 0.13 | D11: 0.15 | E11: 稅收優惠退場假設
A12: 2029E S&M 佔收入比例 | B12: 0.205 | C12: 0.225 | D12: 0.255 | E12: 樂觀：Temu CAC 穩定；悲觀：持續高促銷支出
A13: CapEx 佔收入比例 | B13: 0.025 | C13: 0.03 | D13: 0.035 | E13: 基礎設施投資水準
A15: 2029E 輸出結果（人民幣百萬元）
A16: 2029E 收入 | B16: 1083500 | C16: 850000 | D16: 590000 | E16: 樂觀 / 基本 / 悲觀情境
A17: 2029E 毛利 | B17: 671770 | C17: 497250 | D17: 318600 | E17: 套用情境毛利率
A18: 2029E EBIT | B18: 390060 | C18: 259250 | D18: 129800 | E18: 套用情境 EBIT 利潤率
A19: 2029E EBITDA | B19: 396060 | C19: 263650 | D19: 133500 | E19: EBIT + 折舊攤銷
A20: 2029E 淨利潤（Non-GAAP） | B20: 358000 | C20: 240000 | D20: 122000 | E20: 扣除利息收入與所得稅後
A21: 2029E Non-GAAP EPS（人民幣） | B21: 238.7 | C21: 160 | D21: 81.3 | E21: 淨利潤 / 15 億股
A22: 2029E Non-GAAP EPS（美元） | B22: 33.15 | C22: 22.22 | D22: 11.29 | E22: 匯率 7.20
A23: 2029E 自由現金流 | B23: 340000 | C23: 235000 | D23: 105000 | E23: 估計無槓桿 FCF
A24: 2029E FCF 利潤率 % | B24: 0.314 | C24: 0.276 | D24: 0.178 | E24: FCF / 收入
A25: 累計 FCF 2025-2029E | B25: 1350000 | C25: 1050000 | D25: 620000 | E25: 5 年合計
A28: 情境邏輯說明
A29: 樂觀情境：
A30: Temu 成功轉型至半託管 + Local-to-Local 模式，完全消化 de minimis 政策變動。拼多多中國以低價護城河持續搶佔份額。營運槓桿推動利潤率擴張。稅收優惠延續。
A32: 基本情境：
A33: Temu 在監管逆風下進行溫和的利潤率壓縮。拼多多中國維持中高個位數穩定成長。透過成本紀律逐步改善營業利潤率。
A35: 悲觀情境：
A36: 多重逆風同時實現：中美關係升級、TikTok Shop/Shein 在 Temu 核心市場搶佔份額、中國消費疲軟持續。SBC 與促銷支出居高不下。稅收優惠逐步退場。

Sheet DCF輸入
A1: PDD Holdings — DCF 輸入（人民幣百萬元）
A2: 供 Task 3 估值使用的無槓桿自由現金流預測
A4: 指標 | B4: 2025E | C4: 2026E | D4: 2027E | E4: 2028E | F4: 2029E
A5: 收入
A6: 收入 | B6: =損益表!F6 | C6: =損益表!G6 | D6: =損益表!H6 | E6: =損益表!I6 | F6: =損益表!J6
A7: YoY 成長率 % | B7: =B6/損益表!E6-1 | C7: =C6/B6-1 | D7: =D6/C6-1 | E7: =E6/D6-1 | F7: =F6/E6-1
A9: EBIT | B9: =損益表!F44 | C9: =損益表!G44 | D9: =損益表!H44 | E9: =損益表!I44 | F9: =損益表!J44
A10: EBIT 利潤率 % | B10: =B9/B6 | C10: =C9/C6 | D10: =D9/D6 | E10: =E9/E6 | F10: =F9/F6
A11: 實際稅率 % | B11: 0.13 | C11: 0.135 | D11: 0.14 | E11: 0.145 | F11: 0.15
A12: NOPAT（EBIT × (1-T)） | B12: =B9*(1-B11) | C12: =C9*(1-C11) | D12: =D9*(1-D11) | E12: =E9*(1-E11) | F12: =F9*(1-F11)
A14: 加：折舊與攤銷 | B14: =損益表!F36 | C14: =損益表!G36 | D14: =損益表!H36 | E14: =損益表!I36 | F14: =損益表!J36
A15: 減：資本支出 | B15: =現金流量表!F19 | C15: =現金流量表!G19 | D15: =現金流量表!H19 | E15: =現金流量表!I19 | F15: =現金流量表!J19
A16: 減：Δ 淨營運資金 | B16: -18000 | C16: -16500 | D16: -15500 | E16: -13500 | F16: -11500
A18: 無槓桿自由現金流（UFCF） | B18: =B12+B14+B15+B16 | C18: =C12+C14+C15+C16 | D18: =D12+D14+D15+D16 | E18: =E12+E14+E15+E16 | F18: =F12+F14+F15+F16
A19: UFCF 利潤率 % | B19: =B18/B6 | C19: =C18/C6 | D19: =D18/D6 | E19: =E18/E6 | F19: =F18/F6
A22: 終值年（2029E）關鍵指標
A23: 2029E 收入 | B23: =F6
A24: 2029E EBITDA | B24: =損益表!J41
A25: 2029E EBIT | B25: =F9
A26: 2029E NOPAT | B26: =F12
A27: 2029E 無槓桿 FCF | B27: =F18
A30: 供 Task 3 估值參考
A31: 淨現金（現金 + 短期投資 - 負債），截至 2024 | B31: 433000 | C31: 依 2024A 資產負債表
A32: 稀釋後流通 ADS（百萬股） | B32: 1450 | C32: FY2024
A33: 參考市值（美元十億） | B33: 150 | C33: PDD 股價約 $110-115（2026 年 5 月）
A34: 參考企業價值（美元十億） | B34: 90 | C34: 市值 - 淨現金
A35: USD/RMB 匯率 | B35: 7.2 | C35: 連結至封面與假設
A36: 建議 WACC 區間 | B36: 10.0% - 11.5% | C36: 中國折讓 + 權益成本加權
A37: 建議永續成長率 g 區間 | B37: 2.5% - 3.5% | C37: 長期 GDP + 電商滲透率提升
A38: 建議方法論 | B38: DCF + 可比公司分析（BABA, JD, AMZN, MELI, SE, SHOP） | C38: 供 Task 3 使用
